<mujoco model="maze">
<option timestep="0.01" />
    <worldbody>
<!-- メイン光源を上から追加 -->
<light pos="0 0 3" dir="0 0 -1" diffuse="1 1 1" specular="0.5 0.5 0.5" directional="true"/>
<!-- サブ光源を複数の角度から追加 -->
<light pos="2 -2 2" dir="-1 1 -1" diffuse="0.5 0.5 0.5" specular="0.3 0.3 0.3" directional="true"/>
<light pos="-2 2 2" dir="1 -1 -1" diffuse="0.5 0.5 0.5" specular="0.3 0.3 0.3" directional="true"/>

       <!-- <body pos="-1.27 -1.18 0.0126" euler="0 0 90" name="mouse_body"> -->
        <body pos="0.09 0.09 0.0126" euler="0 0 0" name="mouse_body">
            <joint name='slider_x' type='slide' pos='0 0 0' axis='1 0 0'/>
            <joint name='slider_y' type='slide' pos='0 0 0' axis='0 1 0'/>
            <joint name='slider_z' type='slide' pos='0 0 0' axis='0 0 1' limited="true" range='0 0.035'/>
            <joint name="yaw" type="hinge" axis="0 0 1" limited="false" damping="0" />
            <!-- <joint name="roll" type="hinge" axis="1 0 0" limited="false" damping="0" /> -->
            <body name="torso">
                <geom name="mein_body1" type="box" friction="0.0 0.0 0.0" size="0.05 0.03 0.0008" rgba="0.05 0.4 0.15 1" pos="0 0 0.002" mass="4.65e-3"/>
                <geom name="mein_body_chip1" type="box" friction="0.0 0.0 0.0" size="0.00707 0.00707 0.0008" rgba="0.05 0.4 0.15 1" pos="0.04 0.03 0.002" euler="0 0 45" mass="4.65e-3"/>
                <geom name="mein_body_chip2" type="box" friction="0.0 0.0 0.0" size="0.00707 0.00707 0.0008" rgba="0.05 0.4 0.15 1" pos="0.04 -0.03 0.002" euler="0 0 45" mass="4.65e-3"/>
                <geom name="mein_body_chip3" type="box" friction="0.0 0.0 0.0" size="0.00707 0.00707 0.0008" rgba="0.05 0.4 0.15 1" pos="-0.04 0.03 0.002" euler="0 0 45" mass="4.65e-3"/>
                <geom name="mein_body_chip4" type="box" friction="0.0 0.0 0.0" size="0.00707 0.00707 0.0008" rgba="0.05 0.4 0.15 1" pos="-0.04 -0.03 0.002" euler="0 0 45" mass="4.65e-3"/>
                <geom name="mein_body4" type="box" friction="0.0 0.0 0.0" size="0.013 0.04 0.0008"  rgba="0.05 0.4 0.15 1" pos="-0.027 0 0.002" mass="4.65e-3"/>
                <geom name="mein_body5" type="box" friction="0.0 0.0 0.0" size="0.013 0.04 0.0008"  rgba="0.05 0.4 0.15 1" pos="0.027 0 0.002" mass="4.65e-3"/>
                <site name="sizemiru" type="box" size="0.05 0.04 0.0008"  rgba="0.4 0.2 0.5 0" pos="0.0 0 0.00"/>
                <!--接触判定領域（この中に入ってるgeomが接触すると，センサ値としてその値を取得できる）-->
                <site name = "hit_box1" type = "box" size = "0.02 0.043 0.03" pos="0.033 0 0.0225" rgba="1 1 0 0"/>
                <!-- <site name = "hit_box2" type = "box" size = "0.02 0.043 0.00078" pos="-0.033 0 0.003" rgba="1 1 0 0.3"/> -->
                <site name = "hit_box2" type = "box" size = "0.06 0.08 0.03" pos="-0.0 0 0.0225" rgba="1 1 0 0"/>
                <!-- <site name="velocimeter" type="box" size="0.001 0.001 0.001" pos="0 0 0"/> -->
            </body>
            
            <site name="sensor_left_front" type="box" size="0.003 0.003 0.003" pos="0.031 0.036 0.01" zaxis="1 0 0.01" rgba=".5 1 .5 1"/>
              <!-- zaxisの３つめ　0.1でちょい上向き -->
            <site name="sensor_left_side" type="box" size="0.003 0.003 0.003" pos="0.043 0.016 0.01" zaxis="0.25 1 0" rgba=".5 1 .5 1"/>
            <site name="sensor_right_front" type="box" size="0.003 0.003 0.003" pos="0.031 -0.036 0.01" zaxis="1 0 0.01" rgba=".5 1 .5 1"/>
            <site name="sensor_right_side" type="box" size="0.003 0.003 0.003" pos="0.043 -0.016 0.01" zaxis="0.25 -1 0" rgba=".5 1 .5 1"/>
            <!-- <site name = "hit_box1" type = "box" size = "0.02 0.05 0.0005" pos="0.04 0 0.0025" rgba=".5 .2 0 .3"/>
            <site name = "hit_box2" type = "box" size = "0.02 0.05 0.0005" pos="-0.04 0 0.0025" rgba=".5 .2 0 .3"/> -->
            <site name="accerometer" type="sphere" size="0.001 0.001" pos="0 0 0.0"/>
            <site name="gyro" type="box" size="0.001 0.001 0.001" pos="0 0 0" />
            <site name="velocimeter" type="box" size="0.001 0.001 0.001" pos="0 0 0"/>


            <!-- <body name="left wheel" pos="-0.0 0.036 0.0117" zaxis="0 1 0"> -->
             <body name="left wheel" pos="-0.0 0.036 0.0135" zaxis="0 1 0">
                <joint name="left wheel joint" type="hinge" axis="0 0 1" limited="false" damping='9.6e-5' />
                <!-- <joint name="left wheel joint" type="hinge" axis="0 0 1" limited="false" damping='2.6e-8' /> -->
                <!-- <geom name="left_wheel" type="cylinder" size="0.0135 0.0035" friction="1 0 0"  rgba=".3 .3 0.3 1" mass="5e-3"/> -->
                <geom name="left_wheel" type="ellipsoid" size="0.0135 0.0135 0.0035" rgba=".3 .3 0.3 1" mass="5e-3"  friction="0 0 0"/>
                <site type="box" size = "0.0012 0.008 0.004" rgba=".5 1 .5 1"/>
            </body>
            
            <body name="right wheel" pos="-0.0 -0.036 0.0135" zaxis="0 1 0">
                <joint name="right wheel joint" type="hinge" axis="0 0 1" limited="false" damping='9.6e-5' />
                <!-- <joint name="right wheel joint" type="hinge" axis="0 0 1" limited="false" damping='2.6e-8' /> -->
                <!-- <geom type="cylinder" size="0.0135 0.0035" friction="1 0 0" mass="5e-3"/> #直径27mmのタイヤ -->
                <geom name="right_wheel" type="ellipsoid" size="0.0135 0.0135 0.0035" mass="5e-3" friction="0 0 0"/> #直径27mmのタイヤ
                <site type="box" size = "0.0012 0.008 0.004" rgba=".5 1 .5 1"/>
            </body>

            <body name="motorbox1" pos="0 -0.018 0.0135" >
                <geom type="box" size="0.0117 0.0135 0.0117" rgba="0.1 0.1 0.1 1" mass="50e-3"/>
            </body>

            <body name="motorbox2" pos="0 0.018 0.0135">
                <geom type="box" size="0.0117 0.0135 0.0117" rgba="0.1 0.1 0.1 1" mass="50e-3"/>
            </body>

            <body name="core" pos="0 0 0.0135">
                <geom name="core" type="box" size="0.003 0.003 0.003" rgba="1 0 0 1" mass="50e-3"/>
            </body>
            
            <!--トラッキングカメラを装着-->
            <!-- <camera name="camera_name" mode="track" pos="0 0 1" euler="0 -5 -90" fovy="60"/> -->
            <camera name="camera_name" mode="track" pos="-0.4 0 0.8" euler="0 -30 -90" fovy="60"/>
            <camera name="side_name" mode="targetbody" pos="0 0.2 0.2" euler="-40 0 180" fovy="60"/>

             <geom name="hitsafer_mein_body1" type="box" friction="0.0 0.0 0.0" size="0.05 0.03 0.015" rgba="0.05 0.4 0.15 0" pos="0 0 0.03" mass="4.65e-5"/>
                <geom name="hitsafer_mein_body_chip1" type="box" friction="0.0 0.0 0.0" size="0.00707 0.00707 0.015" rgba="0.05 0.4 0.15 0" pos="0.04 0.03 0.03" euler="0 0 45" mass="4.65e-5"/>
                <geom name="hitsafer_mein_body_chip2" type="box" friction="0.0 0.0 0.0" size="0.00707 0.00707 0.015" rgba="0.05 0.4 0.15 0" pos="0.04 -0.03 0.03" euler="0 0 45" mass="4.65e-5"/>
                <geom name="hitsafer_mein_body_chip3" type="box" friction="0.0 0.0 0.0" size="0.00707 0.00707 0.015" rgba="0.05 0.4 0.15 0" pos="-0.04 0.03 0.03" euler="0 0 45" mass="4.65e-5"/>
                <geom name="hitsafer_mein_body_chip4" type="box" friction="0.0 0.0 0.0" size="0.00707 0.00707 0.015" rgba="0.05 0.4 0.15 0" pos="-0.04 -0.03 0.03" euler="0 0 45" mass="4.65e-5"/>
                <geom name="hitsafer_mein_body4" type="box" friction="0.0 0.0 0.0" size="0.013 0.04 0.015"  rgba="0.05 0.4 0.15 0" pos="-0.027 0 0.03" mass="4.65e-5"/>
                <geom name="hitsafer_mein_body5" type="box" friction="0.0 0.0 0.0" size="0.013 0.04 0.015"  rgba="0.05 0.4 0.15 0" pos="0.027 0 0.03" mass="4.65e-5"/>


            
        
        </body>

                <!--ベース板-->
            <body name="base_plate" pos="0.36 0.36 0.015">
        <geom type="plane" mass="100" size="0.45599999999999996 0.45599999999999996 0.006" rgba="0.2 0.2 0.2 1" friction="0.0 0.0 0.0"/>
        </body>

        <!-- Column 1-->
        <body pos="0.0 0.0 0.037">
            <body pos="0 0 -0.0005">
                <geom type="box" mass="0.01" size="0.006 0.006 0.0245" rgba="1 1 1 1"/>
            </body>
        </body>

        <!-- Column 2-->
        <body pos="0.18 0.0 0.037">
            <body pos="0 0 -0.0005">
                <geom type="box" mass="0.01" size="0.006 0.006 0.0245" rgba="1 1 1 1"/>
            </body>
        </body>

        <!-- Column 3-->
        <body pos="0.36 0.0 0.037">
            <body pos="0 0 -0.0005">
                <geom type="box" mass="0.01" size="0.006 0.006 0.0245" rgba="1 1 1 1"/>
            </body>
        </body>

        <!-- Column 4-->
        <body pos="0.54 0.0 0.037">
            <body pos="0 0 -0.0005">
                <geom type="box" mass="0.01" size="0.006 0.006 0.0245" rgba="1 1 1 1"/>
            </body>
        </body>

        <!-- Column 5-->
        <body pos="0.72 0.0 0.037">
            <body pos="0 0 -0.0005">
                <geom type="box" mass="0.01" size="0.006 0.006 0.0245" rgba="1 1 1 1"/>
            </body>
        </body>

        <!-- Column 6-->
        <body pos="0.0 0.18 0.037">
            <body pos="0 0 -0.0005">
                <geom type="box" mass="0.01" size="0.006 0.006 0.0245" rgba="1 1 1 1"/>
            </body>
        </body>

        <!-- Column 7-->
        <body pos="0.18 0.18 0.037">
            <body pos="0 0 -0.0005">
                <geom type="box" mass="0.01" size="0.006 0.006 0.0245" rgba="1 1 1 1"/>
            </body>
        </body>

        <!-- Column 8-->
        <body pos="0.36 0.18 0.037">
            <body pos="0 0 -0.0005">
                <geom type="box" mass="0.01" size="0.006 0.006 0.0245" rgba="1 1 1 1"/>
            </body>
        </body>

        <!-- Column 9-->
        <body pos="0.54 0.18 0.037">
            <body pos="0 0 -0.0005">
                <geom type="box" mass="0.01" size="0.006 0.006 0.0245" rgba="1 1 1 1"/>
            </body>
        </body>

        <!-- Column 10-->
        <body pos="0.72 0.18 0.037">
            <body pos="0 0 -0.0005">
                <geom type="box" mass="0.01" size="0.006 0.006 0.0245" rgba="1 1 1 1"/>
            </body>
        </body>

        <!-- Column 11-->
        <body pos="0.0 0.36 0.037">
            <body pos="0 0 -0.0005">
                <geom type="box" mass="0.01" size="0.006 0.006 0.0245" rgba="1 1 1 1"/>
            </body>
        </body>

        <!-- Column 12-->
        <body pos="0.18 0.36 0.037">
            <body pos="0 0 -0.0005">
                <geom type="box" mass="0.01" size="0.006 0.006 0.0245" rgba="1 1 1 1"/>
            </body>
        </body>

        <!-- Column 13-->
        <body pos="0.36 0.36 0.037">
            <body pos="0 0 -0.0005">
                <geom type="box" mass="0.01" size="0.006 0.006 0.0245" rgba="1 1 1 1"/>
            </body>
        </body>

        <!-- Column 14-->
        <body pos="0.54 0.36 0.037">
            <body pos="0 0 -0.0005">
                <geom type="box" mass="0.01" size="0.006 0.006 0.0245" rgba="1 1 1 1"/>
            </body>
        </body>

        <!-- Column 15-->
        <body pos="0.72 0.36 0.037">
            <body pos="0 0 -0.0005">
                <geom type="box" mass="0.01" size="0.006 0.006 0.0245" rgba="1 1 1 1"/>
            </body>
        </body>

        <!-- Column 16-->
        <body pos="0.0 0.54 0.037">
            <body pos="0 0 -0.0005">
                <geom type="box" mass="0.01" size="0.006 0.006 0.0245" rgba="1 1 1 1"/>
            </body>
        </body>

        <!-- Column 17-->
        <body pos="0.18 0.54 0.037">
            <body pos="0 0 -0.0005">
                <geom type="box" mass="0.01" size="0.006 0.006 0.0245" rgba="1 1 1 1"/>
            </body>
        </body>

        <!-- Column 18-->
        <body pos="0.36 0.54 0.037">
            <body pos="0 0 -0.0005">
                <geom type="box" mass="0.01" size="0.006 0.006 0.0245" rgba="1 1 1 1"/>
            </body>
        </body>

        <!-- Column 19-->
        <body pos="0.54 0.54 0.037">
            <body pos="0 0 -0.0005">
                <geom type="box" mass="0.01" size="0.006 0.006 0.0245" rgba="1 1 1 1"/>
            </body>
        </body>

        <!-- Column 20-->
        <body pos="0.72 0.54 0.037">
            <body pos="0 0 -0.0005">
                <geom type="box" mass="0.01" size="0.006 0.006 0.0245" rgba="1 1 1 1"/>
            </body>
        </body>

        <!-- Column 21-->
        <body pos="0.0 0.72 0.037">
            <body pos="0 0 -0.0005">
                <geom type="box" mass="0.01" size="0.006 0.006 0.0245" rgba="1 1 1 1"/>
            </body>
        </body>

        <!-- Column 22-->
        <body pos="0.18 0.72 0.037">
            <body pos="0 0 -0.0005">
                <geom type="box" mass="0.01" size="0.006 0.006 0.0245" rgba="1 1 1 1"/>
            </body>
        </body>

        <!-- Column 23-->
        <body pos="0.36 0.72 0.037">
            <body pos="0 0 -0.0005">
                <geom type="box" mass="0.01" size="0.006 0.006 0.0245" rgba="1 1 1 1"/>
            </body>
        </body>

        <!-- Column 24-->
        <body pos="0.54 0.72 0.037">
            <body pos="0 0 -0.0005">
                <geom type="box" mass="0.01" size="0.006 0.006 0.0245" rgba="1 1 1 1"/>
            </body>
        </body>

        <!-- Column 25-->
        <body pos="0.72 0.72 0.037">
            <body pos="0 0 -0.0005">
                <geom type="box" mass="0.01" size="0.006 0.006 0.0245" rgba="1 1 1 1"/>
            </body>
        </body>

        <!-- Wall 1-->
        <body pos="0.09 0.0 0.037">
            <body pos="0 0 -0.0005">
                <geom type="box" mass="0.01" size="0.084 0.006 0.0245" rgba="1 1 1 1"/>
            </body>
        </body>

        <!-- Wall 2-->
        <body pos="0.27 0.0 0.037">
            <body pos="0 0 -0.0005">
                <geom type="box" mass="0.01" size="0.084 0.006 0.0245" rgba="1 1 1 1"/>
            </body>
        </body>

        <!-- Wall 3-->
        <body pos="0.44999999999999996 0.0 0.037">
            <body pos="0 0 -0.0005">
                <geom type="box" mass="0.01" size="0.084 0.006 0.0245" rgba="1 1 1 1"/>
            </body>
        </body>

        <!-- Wall 4-->
        <body pos="0.63 0.0 0.037">
            <body pos="0 0 -0.0005">
                <geom type="box" mass="0.01" size="0.084 0.006 0.0245" rgba="1 1 1 1"/>
            </body>
        </body>

        <!-- Wall 5-->
        <body pos="0.27 0.18 0.037">
            <body pos="0 0 -0.0005">
                <geom type="box" mass="0.01" size="0.084 0.006 0.0245" rgba="1 1 1 1"/>
            </body>
        </body>

        <!-- Wall 6-->
        <body pos="0.44999999999999996 0.18 0.037">
            <body pos="0 0 -0.0005">
                <geom type="box" mass="0.01" size="0.084 0.006 0.0245" rgba="1 1 1 1"/>
            </body>
        </body>

        <!-- Wall 7-->
        <body pos="0.27 0.54 0.037">
            <body pos="0 0 -0.0005">
                <geom type="box" mass="0.01" size="0.084 0.006 0.0245" rgba="1 1 1 1"/>
            </body>
        </body>

        <!-- Wall 8-->
        <body pos="0.44999999999999996 0.54 0.037">
            <body pos="0 0 -0.0005">
                <geom type="box" mass="0.01" size="0.084 0.006 0.0245" rgba="1 1 1 1"/>
            </body>
        </body>

        <!-- Wall 9-->
        <body pos="0.09 0.72 0.037">
            <body pos="0 0 -0.0005">
                <geom type="box" mass="0.01" size="0.084 0.006 0.0245" rgba="1 1 1 1"/>
            </body>
        </body>

        <!-- Wall 10-->
        <body pos="0.27 0.72 0.037">
            <body pos="0 0 -0.0005">
                <geom type="box" mass="0.01" size="0.084 0.006 0.0245" rgba="1 1 1 1"/>
            </body>
        </body>

        <!-- Wall 11-->
        <body pos="0.44999999999999996 0.72 0.037">
            <body pos="0 0 -0.0005">
                <geom type="box" mass="0.01" size="0.084 0.006 0.0245" rgba="1 1 1 1"/>
            </body>
        </body>

        <!-- Wall 12-->
        <body pos="0.63 0.72 0.037">
            <body pos="0 0 -0.0005">
                <geom type="box" mass="0.01" size="0.084 0.006 0.0245" rgba="1 1 1 1"/>
            </body>
        </body>

        <!-- Wall 13-->
        <body pos="0.0 0.09 0.037">
            <body pos="0 0 -0.0005">
                <geom type="box" mass="0.01" size="0.006 0.093 0.0245" rgba="1 1 1 1"/>
            </body>
        </body>

        <!-- Wall 14-->
        <body pos="0.72 0.09 0.037">
            <body pos="0 0 -0.0005">
                <geom type="box" mass="0.01" size="0.006 0.093 0.0245" rgba="1 1 1 1"/>
            </body>
        </body>

        <!-- Wall 15-->
        <body pos="0.0 0.27 0.037">
            <body pos="0 0 -0.0005">
                <geom type="box" mass="0.01" size="0.006 0.093 0.0245" rgba="1 1 1 1"/>
            </body>
        </body>

        <!-- Wall 16-->
        <body pos="0.18 0.27 0.037">
            <body pos="0 0 -0.0005">
                <geom type="box" mass="0.01" size="0.006 0.093 0.0245" rgba="1 1 1 1"/>
            </body>
        </body>

        <!-- Wall 17-->
        <body pos="0.54 0.27 0.037">
            <body pos="0 0 -0.0005">
                <geom type="box" mass="0.01" size="0.006 0.093 0.0245" rgba="1 1 1 1"/>
            </body>
        </body>

        <!-- Wall 18-->
        <body pos="0.72 0.27 0.037">
            <body pos="0 0 -0.0005">
                <geom type="box" mass="0.01" size="0.006 0.093 0.0245" rgba="1 1 1 1"/>
            </body>
        </body>

        <!-- Wall 19-->
        <body pos="0.0 0.44999999999999996 0.037">
            <body pos="0 0 -0.0005">
                <geom type="box" mass="0.01" size="0.006 0.093 0.0245" rgba="1 1 1 1"/>
            </body>
        </body>

        <!-- Wall 20-->
        <body pos="0.18 0.44999999999999996 0.037">
            <body pos="0 0 -0.0005">
                <geom type="box" mass="0.01" size="0.006 0.093 0.0245" rgba="1 1 1 1"/>
            </body>
        </body>

        <!-- Wall 21-->
        <body pos="0.54 0.44999999999999996 0.037">
            <body pos="0 0 -0.0005">
                <geom type="box" mass="0.01" size="0.006 0.093 0.0245" rgba="1 1 1 1"/>
            </body>
        </body>

        <!-- Wall 22-->
        <body pos="0.72 0.44999999999999996 0.037">
            <body pos="0 0 -0.0005">
                <geom type="box" mass="0.01" size="0.006 0.093 0.0245" rgba="1 1 1 1"/>
            </body>
        </body>

        <!-- Wall 23-->
        <body pos="0.0 0.63 0.037">
            <body pos="0 0 -0.0005">
                <geom type="box" mass="0.01" size="0.006 0.093 0.0245" rgba="1 1 1 1"/>
            </body>
        </body>

        <!-- Wall 24-->
        <body pos="0.72 0.63 0.037">
            <body pos="0 0 -0.0005">
                <geom type="box" mass="0.01" size="0.006 0.093 0.0245" rgba="1 1 1 1"/>
            </body>
        </body>
    </worldbody>

    <actuator>
        <!-- <motor name="right" joint="right wheel joint" gear="1.8e-3" ctrllimited="true" ctrlrange="-3 3"/> ctrlrangeで入力の値の範囲を決められる -->
        <!-- <motor name="left" joint="left wheel joint" gear="1.8e-3" ctrllimited="true" ctrlrange="-3 3"/> -->
        <!-- <motor name="right" joint="right wheel joint" gear="9.0e-3" ctrllimited="true" ctrlrange="-0.2 0.2"/> ctrlrangeで入力の値の範囲を決められる
        <motor name="left"  joint="left wheel joint"  gear="9.0e-3" ctrllimited="true" ctrlrange="-0.2 0.2"/> -->
        <motor name="right" joint="right wheel joint" gear="9.0e-3" ctrllimited="true" ctrlrange="-1 1"/> ctrlrangeで入力の値の範囲を決められる
        <motor name="left"  joint="left wheel joint"  gear="9.0e-3" ctrllimited="true" ctrlrange="-1 1"/>
    </actuator>

    <sensor>
        <rangefinder name="LF" site="sensor_left_front" cutoff="0.3"/>
        <rangefinder name="LS" site="sensor_left_side" cutoff="0.3"/>
        <rangefinder name="RF" site="sensor_right_front" cutoff="0.3"/>
        <rangefinder name="RS" site="sensor_right_side" cutoff="0.3"/>
        <touch name = "HB1" site = "hit_box1"/>
        <touch name = "HB2" site = "hit_box2"/>
        <accelerometer name="Accel" site="accerometer"/>
        <gyro name="Gyro" site="gyro" noise="0.0001"/>
        <velocimeter name="Veloci" site="velocimeter"/>
    </sensor>

</mujoco>
                   